<?xml version="1.0" encoding="utf-8"?>
<!-- This URDF was automatically created by SolidWorks to URDF Exporter! Originally created by Stephen Brawner (brawner@gmail.com) 
     Commit Version: 1.4.2-24-gbb9f3a8  Build Version: 1.4.6886.26346
     For more information, please see http://wiki.ros.org/sw_urdf_exporter -->
<robot
  name="LMBH521">
  <link name="world" />
  <joint name="world_joint" type="fixed">
    <parent link="world" />
    <child link = "base_link" />
    <origin xyz="0.0 0.0 0.0" rpy="0.0 0.0 0.0" />
  </joint>
  <!-- ROS base_link to ROCR6 'Base' Coordinates transform -->
    <link name="base"/>
    <joint name="base_link-base_fixed_joint" type="fixed">
      <!-- NOTE: this rotation is only needed as long as base_link itself is
                 not corrected wrt the real robot (ie: rotated over 180
                 degrees)
      -->
      <origin xyz="0 0 0" rpy="0 0 -3.1415926536"/>
      <parent link="base_link"/>
      <child link="base"/>
    </joint>
  <link
    name="base_link">
    <inertial>
      <origin
        xyz="0.36502 0.098589 -0.14731"
        rpy="0 0 0" />
      <mass
        value="0.76049" />
      <inertia
        ixx="0.0058317"
        ixy="2.2712E-05"
        ixz="-5.799E-05"
        iyy="0.004483"
        iyz="-2.8445E-07"
        izz="0.0099036" />
    </inertial>
    <visual>
      <origin
        xyz="0 0 0"
        rpy="-1.57 0 0" />
      <geometry>
        <mesh
          filename="package://LMBH521/meshes/base_link.STL" />
      </geometry>
      <material
        name="">
        <color
          rgba="0.1 0.2 0.25 1" />
      </material>
    </visual>
    <collision>
      <origin
        xyz="0 0 0"
        rpy="0 0 0" />
      <geometry>
        <mesh
          filename="package://LMBH521/meshes/base_link.STL" />
      </geometry>
    </collision>
  </link>
  <link
    name="Link1">
    <inertial>
      <origin
        xyz="5.6664E-06 0.13665 -0.051764"
        rpy="0 0 0" />
      <mass
        value="2.611" />
      <inertia
        ixx="0.0054807"
        ixy="6.4389E-06"
        ixz="3.9942E-06"
        iyy="0.0084216"
        iyz="-1.8695E-06"
        izz="0.0070404" />
    </inertial>
    <visual>
      <origin
        xyz="0 0 0"
        rpy="0 0 0" />
      <geometry>
        <mesh
          filename="package://LMBH521/meshes/Link1.STL" />
      </geometry>
      <material
        name="">
        <color
          rgba="0.1 0.2 0.9 1" />
      </material>
    </visual>
    <collision>
      <origin
        xyz="0 0 0"
        rpy="0 0 0" />
      <geometry>
        <mesh
          filename="package://LMBH521/meshes/Link1.STL" />
      </geometry>
    </collision>
  </link>
  <joint
    name="joint1"
    type="revolute">
    <origin
      xyz="0.313 0.097 -0.16"
      rpy="0 0 3.14" />
    <parent
      link="base_link" />
    <child
      link="Link1" />
    <axis
      xyz="0 0 1" />
    <limit
      lower="-3.14"
      upper="3.14"
      effort="20"
      velocity="1.6" />
    <safety_controller
      k_velocity="0" />
  </joint>
  <link
    name="Link2">
    <inertial>
      <origin
        xyz="0.10961 0.0011818 0.046165"
        rpy="0 0 0" />
      <mass
        value="1.3533" />
      <inertia
        ixx="0.0012262"
        ixy="-8.8931E-06"
        ixz="1.2654E-05"
        iyy="0.00176"
        iyz="1.6266E-06"
        izz="0.0023721" />
    </inertial>
    <visual>
      <origin
        xyz="0 0 0"
        rpy="0 0 0" />
      <geometry>
        <mesh
          filename="package://LMBH521/meshes/Link2.STL" />
      </geometry>
      <material
        name="">
        <color
          rgba="0.1 0.2 0.9 1" />
      </material>
    </visual>
    <collision>
      <origin
        xyz="0 0 0"
        rpy="0 0 0" />
      <geometry>
        <mesh
          filename="package://LMBH521/meshes/Link2.STL" />
      </geometry>
    </collision>
  </link>
  <joint
    name="joint2"
    type="revolute">
    <origin
      xyz="0 -0.003 0.26"
      rpy="1.57 0 0" />
    <parent
      link="Link1" />
    <child
      link="Link2" />
    <axis
      xyz="0 0 -1" />
    <limit
      lower="-2.5"
      upper="2.5"
      effort="40.2"
      velocity="1.6" />
    <safety_controller
      k_velocity="0" />
  </joint>
  <link
    name="Link3">
    <inertial>
      <origin
        xyz="-0.00032446 -0.0066734 -0.040728"
        rpy="0 0 0" />
      <mass
        value="0.46331" />
      <inertia
        ixx="0.00033467"
        ixy="-1.6492E-05"
        ixz="-3.7134E-06"
        iyy="0.00047747"
        iyz="3.4419E-06"
        izz="0.00072169" />
    </inertial>
    <visual>
      <origin
        xyz="0 0 0"
        rpy="0 0 0" />
      <geometry>
        <mesh
          filename="package://LMBH521/meshes/Link3.STL" />
      </geometry>
      <material
        name="">
        <color
          rgba="0.1 0.2 0.9 1" />
      </material>
    </visual>
    <collision>
      <origin
        xyz="0 0 0"
        rpy="0 0 0" />
      <geometry>
        <mesh
          filename="package://LMBH521/meshes/Link3.STL" />
      </geometry>
    </collision>
  </link>
  <joint
    name="joint3"
    type="revolute">
    <origin
      xyz="0 0.24 -0.004"
      rpy="0 0 0" />
    <parent
      link="Link2" />
    <child
      link="Link3" />
    <axis
      xyz="0 0 1" />
    <limit
      lower="-2.5"
      upper="2.5"
      effort="20.7"
      velocity="1.6" />
    <safety_controller
      k_velocity="0" />
  </joint>
  <link
    name="Link4">
    <inertial>
      <origin
        xyz="-0.00646 0.00043659 0.058444"
        rpy="0 0 0" />
      <mass
        value="0.9255" />
      <inertia
        ixx="0.00064254"
        ixy="-1.5847E-07"
        ixz="1.7938E-07"
        iyy="0.00062074"
        iyz="2.7497E-07"
        izz="0.00036216" />
    </inertial>
    <visual>
      <origin
        xyz="0 0 0"
        rpy="0 0 0" />
      <geometry>
        <mesh
          filename="package://LMBH521/meshes/Link4.STL" />
      </geometry>
      <material
        name="">
        <color
          rgba="0.1 0.2 0.9 1" />
      </material>
    </visual>
    <collision>
      <origin
        xyz="0 0 0"
        rpy="0 0 0" />
      <geometry>
        <mesh
          filename="package://LMBH521/meshes/Link4.STL" />
      </geometry>
    </collision>
  </link>
  <joint
    name="joint4"
    type="revolute">
    <origin
      xyz="0 0.23 0"
      rpy="-1.57 0 0" />
    <parent
      link="Link3" />
    <child
      link="Link4" />
    <axis
      xyz="0 0 1" />
    <limit
      lower="-3.14"
      upper="3.14"
      effort="12"
      velocity="1.6" />
    <safety_controller
      k_velocity="0" />
  </joint>
  <link
    name="Link5">
    <inertial>
      <origin
        xyz="-0.017709 0.0082874 0.0015222"
        rpy="0 0 0" />
      <mass
        value="0.37783" />
      <inertia
        ixx="0.000242"
        ixy="-3.1292E-06"
        ixz="2.2249E-06"
        iyy="0.00027078"
        iyz="-4.451E-07"
        izz="0.00030379" />
    </inertial>
    <visual>
      <origin
        xyz="0 0 0"
        rpy="0 0 0" />
      <geometry>
        <mesh
          filename="package://LMBH521/meshes/Link5.STL" />
      </geometry>
      <material
        name="">
        <color
          rgba="0.1 0.2 0.9 1" />
      </material>
    </visual>
    <collision>
      <origin
        xyz="0 0 0"
        rpy="0 0 0" />
      <geometry>
        <mesh
          filename="package://LMBH521/meshes/Link5.STL" />
      </geometry>
    </collision>
  </link>
  <joint
    name="joint5"
    type="revolute">
    <origin
      xyz="0 0 0"
      rpy="-1.57 0 -3.14" />
    <parent
      link="Link4" />
    <child
      link="Link5" />
    <axis
      xyz="0 0 -1" />
    <limit
      lower="-2.5"
      upper="2.5"
      effort="12"
      velocity="1.6" />
    <safety_controller
      k_velocity="0" />
  </joint>
  <link
    name="Link6">
    <inertial>
      <origin
        xyz="-1.4201E-10 4.9088E-09 0.021"
        rpy="0 0 0" />
      <mass
        value="0.0021112" />
      <inertia
        ixx="3.1878E-07"
        ixy="4.7976E-22"
        ixz="2.0416E-15"
        iyy="3.1878E-07"
        iyz="-7.0569E-14"
        izz="1.6889E-08" />
    </inertial>
    <visual>
      <origin
        xyz="0 0 0"
        rpy="0 0 0" />
      <geometry>
        <mesh
          filename="package://LMBH521/meshes/Link6.STL" />
      </geometry>
      <material
        name="">
        <color
          rgba="0.79216 0.81961 0.93333 1" />
      </material>
    </visual>
    <collision>
      <origin
        xyz="0 0 0"
        rpy="0 0 0" />
      <geometry>
        <mesh
          filename="package://LMBH521/meshes/Link6.STL" />
      </geometry>
    </collision>
  </link>
  <joint
    name="joint6"
    type="revolute">
    <origin
      xyz="0 -0.07 0"
      rpy="1.57 0 0" />
    <parent
      link="Link5" />
    <child
      link="Link6" />
    <axis
      xyz="0 0 -1" />
    <limit
      lower="-3.14"
      upper="3.14"
      effort="10"
      velocity="1.6" />
    <safety_controller
      k_velocity="0" />
  </joint>
</robot>